Workbook

Sheet Instructions
B2: Use Case → Sprint Task Tracker
B4: 1. Use Cases | C4: Define each use case first on the 'Use Cases' tab. One row per use case. Fill only the yellow cells; formulas/IDs elsewhere are for reference.
B6: 2. Sprint Tasks | C6: Break every use case into one or more sprint-ready tasks on the 'Sprint Tasks' tab. Link each task back to its Use Case ID.
B8: 3. Sprint Board | C8: The 'Sprint Board' tab summarizes task counts and status per sprint using formulas — do not edit its formula cells directly.
B10: 4. Dropdowns | C10: Priority, Status, Task Type and Sprint columns use dropdown lists so data stays consistent. Edit the 'Lookup Lists' tab to change the available options.
B12: Color legend
C14: Yellow fill = cell you fill in
C15: Green fill = example row (for reference only, safe to delete/overwrite)

Sheet Lookup Lists
A1: Priority | B1: UC Status | C1: Task Status | D1: Task Type | E1: Sprint
A2: Critical | B2: Draft | C2: To Do | D2: Frontend | E2: Sprint 1
A3: High | B3: Approved | C3: In Progress | D3: Backend | E3: Sprint 2
A4: Medium | B4: In Progress | C4: In Review | D4: API | E4: Sprint 3
A5: Low | B5: Done | C5: Blocked | D5: Database | E5: Sprint 4
C6: Done | D6: QA/Testing | E6: Sprint 5
D7: DevOps | E7: Backlog
D8: Documentation
D9: Design

Sheet Use Cases
A1: Use Case ID | B1: Use Case Title | C1: Actor | D1: Description | E1: Preconditions | F1: Main Flow (steps) | G1: Postconditions | H1: Priority | I1: Status | J1: Related Epic/Feature | K1: Notes
A2: UC-001 | B2: Register with email and password | C2: Student (prospect) | D2: As a prospective student, I want to create an account with my email and a password so that I can start using Lumen Academy. | E2: Email is not already registered (checked via GET /auth/email-exists); Supabase Auth is reachable. | F2: 1. Open the landing page and choose Register 2. Enter name, email, password 3. Frontend checks email availability 4. signUpWithPassword() creates the Supabase identity 5. A 6-digit confirmation OTP is emailed 6. Student is moved to the OTP screen | G2: A Supabase auth identity and a core.app_user row exist; the account is pending email confirmation. | H2: Critical | I2: Done | J2: Auth & Session | K2: frontend/src/pages/LandingView.tsx (authMode 'register'), services/supabaseAuth.ts signUpWithPassword, services/emailAvailabilityApi.ts. Auth is 100% client-side Supabase; backend never issues tokens.
A3: UC-002 | B3: Confirm sign-up with an email OTP | C3: Student (prospect) | D3: As a new student, I want to confirm my email with the code I received so that my account becomes usable. | E3: Sign-up completed; a confirmation OTP was sent and has not expired. | F3: 1. Enter the 6 digits in the OTP boxes 2. verifySignupOtp() exchanges the code for a session 3. On failure the student can request a resend (rate-limited by a retry-after countdown) 4. On success the app loads the authenticated shell | G3: Email is confirmed, a Supabase session exists and the student lands on the dashboard. | H3: Critical | I3: Done | J3: Auth & Session | K3: supabaseAuth.ts verifySignupOtp / resendSignupConfirmation; resend guarded by services/emailSendGuard.ts.
A4: UC-003 | B4: Sign in with email and password | C4: Student | D4: As a returning student, I want to sign in with my email and password so that I can get back to my preparation. | E4: A confirmed account exists. | F4: 1. Choose Sign In 2. Enter email and password 3. signInWithPassword() returns a Supabase session 4. GET /me returns identity, role, status, tenancy and student profile in one call 5. The dashboard renders | G4: An authenticated session is active and the profile snapshot is cached in app state. | H4: Critical | I4: Done | J4: Auth & Session | K4: supabaseAuth.ts signInWithPassword; backend/src/routes/api.ts GET /me (replaces the old multi-round-trip PostgREST reads).
A5: UC-004 | B5: Sign in with a one-time passcode (email) | C5: Student | D5: As a student who does not want to remember a password, I want to sign in with an emailed code so that access stays simple. | E5: The email belongs to an existing account (shouldCreateUser=false for the login flow). | F5: 1. Choose Sign In and switch delivery to Email OTP 2. sendEmailOtp() dispatches the code 3. Enter the 6 digits 4. verifyEmailOtp() returns a session | G5: The student is signed in without a password. | H5: High | I5: Done | J5: Auth & Session | K5: supabaseAuth.ts sendEmailOtp / verifyEmailOtp; otpFlow distinguishes register vs login.
A6: UC-005 | B6: Sign in with a mobile OTP | C6: Student | D6: As a student who prefers my phone number, I want to receive an SMS code so that I can sign in without email. | E6: Phone number is valid and normalisable to E.164; SMS provider is configured in Supabase. | F6: 1. Switch OTP delivery to Phone 2. Enter the mobile number (converted to E.164) 3. sendPhoneOtp() dispatches the SMS 4. Enter the code 5. verifyPhoneOtp() returns a session | G6: The student is signed in via phone identity. | H6: Medium | I6: In Progress | J6: Auth & Session | K6: supabaseAuth.ts sendPhoneOtp / verifyPhoneOtp. docs/FRONTEND.md sec 5.6 flags the per-SMS cost trap before this is switched on for real traffic.
A7: UC-006 | B7: Sign in with Google or LinkedIn | C7: Student | D7: As a student, I want to sign in with an account I already have so that I skip form filling. | E7: The OAuth provider is enabled in Supabase and redirect URLs are allow-listed. | F7: 1. Click Continue with Google (or LinkedIn) 2. signInWithGoogle()/signInWithLinkedIn() starts the OAuth redirect 3. Provider returns to the app with a session 4. GET /me resolves the app user | G7: A federated identity is linked and the student is signed in. | H7: Medium | I7: Done | J7: Auth & Session | K7: supabaseAuth.ts signInWithGoogle / signInWithLinkedIn; services/googleOneTap.ts for the One Tap prompt.
A8: UC-007 | B8: Explore the product on the shared demo account | C8: Visitor | D8: As a visitor, I want a one-click demo login so that I can see the real product before registering. | E8: Demo credentials are provisioned; ensureDemoSession() can sign in or create the demo user once. | F8: 1. Click Demo Account on the landing page 2. ensureDemoSession() signs in (or provisions) the shared demo user 3. The app shows a 'demo data' badge in the header 4. Visitor browses dashboard, tests and analytics | G8: The visitor is inside the authenticated app on shared sample data. | H8: High | I8: Done | J8: Auth & Session | K8: frontend/src/services/demoSession.ts; Header.tsx renders the demo badge with a shared-account tooltip.
A9: UC-008 | B9: Reset the demo account back to a clean state | C9: Student (demo) / Support | D9: As anyone using the demo, I want its data reset so that the next visitor sees a clean account. | E9: Signed in on the demo account. | F9: 1. Trigger the demo reset action 2. POST /auth/demo/reset clears demo attempts, plans and notes 3. The app reloads its state | G9: Demo attempts and learn-layer rows are cleared; the demo user itself survives. | H9: Low | I9: Done | J9: Auth & Session | K9: backend/src/controllers/demoController.ts resetDemoAccountData; frontend services/demoSession.ts.
A10: UC-009 | B10: Check whether an email is already registered | C10: Student (prospect) | D10: As a prospect, I want to be told immediately that my email already has an account so that I sign in instead of re-registering. | E10: Lookup rate limit for the caller has not been exceeded. | F10: 1. Type an email in the register form 2. Frontend calls GET /auth/email-exists (debounced) 3. checkEmailLookupAllowed() throttles abusive lookups 4. UI shows 'already registered — sign in instead' | G10: The student is routed to the correct flow before submitting. | H10: Medium | I10: Done | J10: Auth & Session | K10: backend/src/services/emailAvailability.service.ts; deliberately rate-limited to avoid an email-enumeration oracle.
A11: UC-010 | B11: Keep the session alive and warn before idle expiry | C11: Student | D11: As a student, I want a warning before my session expires so that I do not lose work silently. | E11: Signed in; SESSION_IDLE_TIMEOUT_MINUTES / SESSION_ABSOLUTE_HOURS configured. | F11: 1. The client sends POST /auth/session/heartbeat on activity 2. GET /auth/session reports idle and absolute remaining time 3. useIdleSessionGuard opens SessionExpiryModal before the cut-off 4. Student extends the session or is signed out | G11: The session is either extended or ended cleanly with the student informed. | H11: High | I11: Done | J11: Auth & Session | K11: backend/src/controllers/authSessionController.ts; frontend hooks/useIdleSessionGuard.ts + components/layout/SessionExpiryModal.tsx.
A12: UC-011 | B12: Sign out | C12: Student | D12: As a student, I want to sign out so that my account is not left open on a shared device. | E12: An active session exists. | F12: 1. Open the profile menu and click Sign Out 2. POST /auth/session/logout records the logout 3. supabaseAuth.signOut() clears the client session 4. The landing page is shown | G12: The session is terminated and cached profile state is dropped. | H12: High | I12: Done | J12: Auth & Session | K12: authSessionController.logoutSession; Header.tsx sign-out control.
... A82: UC-081 | B82: Enforce record ownership on user-scoped data | C82: System | D82: As the platform, I want every attempt, plan and deck read/write checked against its owner so that one student can never touch another's data. | E82: The caller is authenticated. | F82: 1. requireAttemptOwnership() resolves the attempt's owner once per request 2. requirePlanOwnership() / requireDeckOwnership() do the same for plans and flashcard decks 3. makeOwnedCrudRouter scopes generic learn CRUD by user_id 4. A mismatch returns 403/404 without exposing the record | G82: Cross-user access is impossible through any owned route. | H82: Critical | I82: Done | J82: Platform & Operations | K82: backend/src/middleware/ownership.ts; backend/src/lib/dbCrudRouter.ts. audit_log is deliberately not exposed through CRUD (append-only).

Sheet Sprint Tasks
A1: Task ID | B1: Use Case ID | C1: Task Title | D1: Task Type | E1: Description | F1: Acceptance Criteria | G1: Sprint | H1: Assignee | I1: Story Points | J1: Priority | K1: Status | L1: Start Date | M1: Due Date
A2: TASK-001 | B2: UC-034 | C2: Build test timer & auto-submit component | D2: Frontend | E2: Implement countdown timer UI that auto-submits the test when time expires. | F2: Given a running test, when the timer hits 0, then the test auto-submits and shows the result screen. | G2: Sprint 1 | H2: Deepan B | I2: 5 | J2: High | K2: In Progress | L2: 2026-09-08 | M2: 2026-09-12
A3: ="TASK-"&TEXT(2,"000") | B3: UC-001 | C3: Email + password registration | D3: Frontend | E3: Register form on LandingView (authMode 'register') calling supabaseAuth.signUpWithPassword, with client-side Supabase auth only — the backend never issues tokens. | F3: Given a new email, when the form is submitted, then a Supabase identity and a core.app_user row exist and the OTP screen is shown. | G3: Sprint 1 | H3: FE Dev | I3: 5 | J3: Critical | K3: Done | L3: 46273 | M3: 46277
A4: ="TASK-"&TEXT(3,"000") | B4: UC-002 | C4: Sign-up OTP confirmation + resend guard | D4: Frontend | E4: 6-digit OTP screen wired to verifySignupOtp / resendSignupConfirmation, with resend throttled by services/emailSendGuard.ts. | F4: Given a valid code, when it is entered, then the email is confirmed and a session starts; resend is blocked inside the guard window. | G4: Sprint 1 | H4: FE Dev | I4: 3 | J4: Critical | K4: Done | L4: 46273 | M4: 46277
A5: ="TASK-"&TEXT(4,"000") | B5: UC-003 | C5: Password sign-in with single-call profile load | D5: Frontend | E5: signInWithPassword followed by one GET /me call, replacing the old multi-round-trip PostgREST reads. | F5: Given a confirmed account, when the student signs in, then the profile snapshot loads in a single request. | G5: Sprint 1 | H5: FE Dev | I5: 3 | J5: Critical | K5: Done | L5: 46273 | M5: 46277
A6: ="TASK-"&TEXT(5,"000") | B6: UC-004 | C6: Passwordless email OTP sign-in | D6: Frontend | E6: sendEmailOtp / verifyEmailOtp with otpFlow distinguishing register from login (shouldCreateUser=false on login). | F6: Given an existing email, when the emailed code is entered, then the student is signed in without a password. | G6: Sprint 1 | H6: FE Dev | I6: 3 | J6: High | K6: Done | L6: 46273 | M6: 46277
A7: ="TASK-"&TEXT(6,"000") | B7: UC-005 | C7: Mobile OTP sign-in (E.164 normalisation) | D7: Frontend | E7: sendPhoneOtp / verifyPhoneOtp with mobile numbers normalised to E.164 before the request. | F7: Given a valid Indian mobile number, when the SMS code is entered, then the student is signed in via the phone identity. | G7: Sprint 1 | H7: FE Dev | I7: 5 | J7: Medium | K7: In Progress | L7: 46273 | M7: 46284
A8: ="TASK-"&TEXT(7,"000") | B8: UC-005 | C8: SMS cost guard before enabling phone OTP for real traffic | D8: Backend | E8: Per-number and per-IP send limits plus a spend cap, closing the per-SMS cost trap flagged in docs/FRONTEND.md sec 5.6. | F8: Given repeated OTP requests for one number, when the limit is hit, then further sends are refused and the attempt is logged. | G8: Sprint 2 | H8: BE Dev | I8: 3 | J8: Medium | K8: To Do | L8: 46287 | M8: 46298
A9: ="TASK-"&TEXT(8,"000") | B9: UC-006 | C9: Google / LinkedIn OAuth sign-in | D9: Frontend | E9: signInWithGoogle / signInWithLinkedIn plus the Google One Tap prompt in services/googleOneTap.ts. | F9: Given an enabled provider, when the student completes consent, then a federated identity is linked and the session starts. | G9: Sprint 1 | H9: FE Dev | I9: 5 | J9: Medium | K9: Done | L9: 46273 | M9: 46277
A10: ="TASK-"&TEXT(9,"000") | B10: UC-007 | C10: One-click demo login | D10: Frontend | E10: services/demoSession.ts ensureDemoSession plus the shared-account demo badge in Header.tsx. | F10: Given a visitor on the landing page, when Demo Account is clicked, then they land inside the app on sample data with the badge visible. | G10: Sprint 1 | H10: FE Dev | I10: 3 | J10: High | K10: Done | L10: 46273 | M10: 46277
A11: ="TASK-"&TEXT(10,"000") | B11: UC-008 | C11: Demo account reset endpoint | D11: Backend | E11: POST /auth/demo/reset in demoController.resetDemoAccountData clearing attempts and learn-layer rows. | F11: Given the demo account has data, when reset is called, then attempts and learn rows are cleared and the user row survives. | G11: Sprint 1 | H11: BE Dev | I11: 2 | J11: Low | K11: Done | L11: 46273 | M11: 46277
A12: ="TASK-"&TEXT(11,"000") | B12: UC-009 | C12: Email availability lookup with rate limit | D12: Backend | E12: GET /auth/email-availability in emailAvailability.service.ts, rate-limited so it cannot be used as an enumeration oracle. | F12: Given a registered email, when it is typed, then the UI routes to sign-in; repeated lookups from one caller are throttled. | G12: Sprint 1 | H12: BE Dev | I12: 3 | J12: Medium | K12: Done | L12: 46273 | M12: 46277
A13: ="TASK-"&TEXT(12,"000") | B13: UC-010 | C13: Idle session heartbeat and expiry warning | D13: Full-stack | E13: POST /auth/session/heartbeat with useIdleSessionGuard.ts and SessionExpiryModal warning before idle/absolute expiry. | F13: Given an idle session near timeout, when the threshold passes, then the warning modal appears and the student can extend or end cleanly. | G13: Sprint 1 | H13: Full-stack | I13: 5 | J13: High | K13: Done | L13: 46273 | M13: 46277
A14: ="TASK-"&TEXT(13,"000") | B14: UC-011 | C14: Sign out | D14: Frontend | E14: Profile-menu sign-out calling POST /auth/session/logout and dropping cached profile state. | F14: Given a signed-in student, when Sign Out is clicked, then the session ends and no cached profile remains. | G14: Sprint 1 | H14: FE Dev | I14: 1 | J14: High | K14: Done | L14: 46273 | M14: 46277
A15: ="TASK-"&TEXT(14,"000") | B15: UC-003 | C15: Regression pass across all six sign-in paths | D15: QA/Testing | E15: Exercise password, email OTP, phone OTP, Google, LinkedIn and demo sign-in end to end on desktop and mobile widths. | F15: Given each of the six paths, when it is run against a clean account, then sign-in succeeds and GET /me returns the right profile. | G15: Sprint 2 | H15: QA | I15: 5 | J15: High | K15: To Do | L15: 46287 | M15: 46298
A16: ="TASK-"&TEXT(15,"000") | B16: UC-012 | C16: Onboarding sync (exam, class, target year) | D16: Backend | E16: GET /me onboarding sync in meProfile.service.ts persisting targetExam, classLevel and targetYear on core.student_profile. | F16: Given a new student completes onboarding, when GET /me is called, then the three fields are persisted and returned. | G16: Sprint 1 | H16: BE Dev | I16: 5 | J16: High | K16: Done | L16: 46273 | M16: 46277
A17: ="TASK-"&TEXT(16,"000") | B17: UC-013 | C17: Consolidated profile snapshot (GET /me) | D17: Backend | E17: getFullProfile returning identity, role, status, plan and academic details in one authoritative response. | F17: Given a valid access token, when GET /me is called, then one response carries every field ProfileView renders. | G17: Sprint 1 | H17: BE Dev | I17: 3 | J17: High | K17: Done | L17: 46273 | M17: 46277
A18: ="TASK-"&TEXT(17,"000") | B18: UC-014 | C18: Strict self-service profile update | D18: Backend | E18: PATCH /me with a .strict() updateProfileSchema so forbidden fields are rejected rather than silently dropped. | F18: Given a payload containing a non-self-editable field, when it is submitted, then the request is rejected with a field-level error. | G18: Sprint 1 | H18: BE Dev | I18: 3 | J18: High | K18: Done | L18: 46273 | M18: 46277
A19: ="TASK-"&TEXT(18,"000") | B19: UC-015 | C19: Wrap remaining Header and Dashboard strings in t() (DB-05 phase 1) | D19: Frontend | E19: First screen-by-screen pass of the deferred i18n sweep: wrap unwrapped strings and add the missing en.json / ta.json keys for Header and Dashboard. | F19: Given the UI language is Tamil, when Header and Dashboard are opened, then no English string remains and every key resolves. | G19: Sprint 1 | H19: FE Dev | I19: 8 | J19: Medium | K19: In Progress | L19: 46273 | M19: 46284
A20: ="TASK-"&TEXT(19,"000") | B20: UC-015 | C20: Tamil string-coverage sweep across remaining screens (DB-05) | D20: Frontend | E20: Continue the sweep across the other useLanguage() consumers, then run the exit gate: click through every route in Tamil. | F20: Given every route is visited in Tamil, when the click-through completes, then zero untranslated strings are found. | G20: Sprint 3 | H20: FE Dev | I20: 13 | J20: Medium | K20: To Do | L20: 46301 | M20: 46312
A21: ="TASK-"&TEXT(20,"000") | B21: UC-016 | C21: Light / dark theme toggle | D21: Frontend | E21: Header.tsx toggleDarkMode with Tailwind v4 dark: variants and a persisted preference. | F21: Given dark mode is chosen, when the app reloads, then the theme is still dark. | G21: Sprint 1 | H21: FE Dev | I21: 1 | J21: Low | K21: Done | L21: 46273 | M21: 46277
A22: ="TASK-"&TEXT(21,"000") | B22: UC-017 | C22: Persist notification and security preferences server-side | D22: Full-stack | E22: Replace Header.tsx's local useState toggles (twoFactor, dailyReminders, whatsappUpdates, emailDiagnosticReports) with a real preferences table and GET/PATCH endpoints. | F22: Given a toggle is changed, when the app reloads on another device, then the stored value is returned by the API and rendered. | G22: Sprint 2 | H22: Full-stack | I22: 8 | J22: Medium | K22: To Do | L22: 46287 | M22: 46298
A23: ="TASK-"&TEXT(22,"000") | B23: UC-017 | C23: Wire reminder and diagnostic delivery to stored preferences | D23: Backend | E23: Make the reminder, WhatsApp and diagnostic-email senders read the persisted preferences instead of firing unconditionally. | F23: Given a student disables daily reminders, when the scheduler runs, then no reminder is sent to that student. | G23: Sprint 3 | H23: BE Dev | I23: 8 | J23: Medium | K23: To Do | L23: 46301 | M23: 46312
A24: ="TASK-"&TEXT(23,"000") | B24: UC-017 | C24: Two-factor enrolment behind the security toggle | D24: Full-stack | E24: Enrolment, verification and recovery-code flow for the 2FA toggle that today only sets local state. | F24: Given 2FA is enabled, when the student next signs in, then a second factor is required and recovery codes are issued once. | G24: Backlog | H24: Full-stack | I24: 13 | J24: Medium | K24: To Do
A25: ="TASK-"&TEXT(24,"000") | B25: UC-018 | C25: Catalog tree endpoint fetched once per session | D25: Backend | E25: GET /catalog/tree returning exam > subject > unit > chapter > topic, consumed by catalogApi.ts and fetched once in App.tsx. | F25: Given the app loads, when the tree is fetched, then every scope picker is populated from that single response. | G25: Sprint 1 | H25: BE Dev | I25: 5 | J25: High | K25: Done | L25: 46273 | M25: 46277
A26: ="TASK-"&TEXT(25,"000") | B26: UC-019 | C26: NEET course area and syllabus browsing | D26: Frontend | E26: CourseAreaView / CoursesView over data/syllabusData.ts, with the route into unit-scoped practice. | F26: Given the NEET tab, when a unit is opened, then its chapters render and Build Test starts a scoped attempt. | G26: Sprint 1 | H26: FE Dev | I26: 5 | J26: High | K26: In Progress | L26: 46273 | M26: 46284
A27: ="TASK-"&TEXT(26,"000") | B27: UC-019 | C27: Replace empty JEE tabs with an explicit coming-soon state | D27: Frontend | E27: The JEE Mains and Advanced tabs are deliberate placeholders today and render blank; give them an honest empty state. | F27: Given the JEE tab is opened, when no syllabus exists, then a clear coming-soon panel is shown instead of an empty page. | G27: Sprint 4 | H27: FE Dev | I27: 2 | J27: Low | K27: To Do | L27: 46315 | M27: 46326
A28: ="TASK-"&TEXT(27,"000") | B28: UC-020 | C28: Unit study material preview and download | D28: Full-stack | E28: unitMaterialController redirect plus the frontend content-type check that stops a Google sign-in page being saved as a fake PDF. | F28: Given a shared Drive file, when download is clicked, then a valid file is saved; given an unshared one, a single clear message is shown. | G28: Sprint 1 | H28: Full-stack | I28: 3 | J28: High | K28: In Progress | L28: 46273 | M28: 46284
A29: ="TASK-"&TEXT(28,"000") | B29: UC-020 | C29: Re-verify Drive material access after sharing is fixed (DB-06) | D29: QA/Testing | E29: All 82 learn.unit_material rows point at Drive files that are not link-shared. Blocked on the Drive owner changing sharing, then re-run db/scripts/check-drive-material-access.ts. | F29: Given sharing is set to Anyone with the link, when the script runs, then all 82 files return the file rather than a sign-in wall. | G29: Sprint 2 | H29: Content Ops | I29: 2 | J29: High | K29: Blocked | L29: 46287 | M29: 46298
A30: ="TASK-"&TEXT(29,"000") | B30: UC-021 | C30: Expose the resource library book list through an API | D30: Backend | E30: Load db/books/I20_23_Resource_Library_Book_List_REAL.json behind a read route; today the data exists with no endpoint. | F30: Given the endpoint is called, when a subject filter is passed, then the matching books are returned with their metadata. | G30: Sprint 3 | H30: BE Dev | I30: 5 | J30: Low | K30: To Do | L30: 46301 | M30: 46312
A31: ="TASK-"&TEXT(30,"000") | B31: UC-021 | C31: Resource library browse screen | D31: Frontend | E31: First UI over the book list: browse by subject, open a book's details. | F31: Given the library is opened, when a subject is chosen, then its recommended books render from the API. | G31: Sprint 3 | H31: FE Dev | I31: 5 | J31: Low | K31: To Do | L31: 46301 | M31: 46312
A32: ="TASK-"&TEXT(31,"000") | B32: UC-022 | C32: Subject / chapter / topic practice configurator | D32: Full-stack | E32: TestListView configuration plus sessionController.createSession, a discriminated union over the four test modes. | F32: Given a scope and count, when Start is pressed, then a published assess.test and a live attempt exist. | G32: Sprint 1 | H32: Full-stack | I32: 8 | J32: Critical | K32: Done | L32: 46273 | M32: 46277
A33: ="TASK-"&TEXT(32,"000") | B33: UC-025 | C33: Image-only practice mode | D33: Backend | E33: sessionController mode 'image-practice' with asset-resolver and QuestionImage handling the diagram items. | F33: Given the image mode, when the attempt is built, then every question carries an image and a short pool fails clearly. | G33: Sprint 1 | H33: BE Dev | I33: 5 | J33: Medium | K33: Done | L33: 46273 | M33: 46277
A34: ="TASK-"&TEXT(33,"000") | B34: UC-026 | C34: Full NEET mock with practice-first gate | D34: Backend | E34: sessionController mode 'full-mock' plus the hasCompletedPracticeTest gate before a full paper can start. | F34: Given no completed practice test, when Mock Test is clicked, then the gate explains why; otherwise a full sectioned attempt starts. | G34: Sprint 1 | H34: BE Dev | I34: 5 | J34: Critical | K34: Done | L34: 46273 | M34: 46277
A35: ="TASK-"&TEXT(34,"000") | B35: UC-027 | C35: Custom multi-scope paper | D35: Frontend | E35: Mode 'custom' with TestListView.distributeCount spreading the requested total across the chosen buckets. | F35: Given several scopes and a total, when the test starts, then the counts are distributed and every scope is represented. | G35: Sprint 1 | H35: FE Dev | I35: 5 | J35: High | K35: Done | L35: 46273 | M35: 46277
A36: ="TASK-"&TEXT(35,"000") | B36: UC-028 | C36: Launch a test from a course unit or plan goal | D36: Frontend | E36: CoursesView / StudyPlanView name-match handoff into the test configurator. | F36: Given a unit or goal, when Build Test is clicked, then the attempt starts pre-scoped to it. | G36: Sprint 1 | H36: FE Dev | I36: 3 | J36: Medium | K36: Done | L36: 46273 | M36: 46277
A37: ="TASK-"&TEXT(36,"000") | B37: UC-028 | C37: Replace the name-match handoff with catalog ids | D37: Frontend | E37: Local syllabus strings are matched to catalog nodes by name today; carry the real uuid through the handoff instead. | F37: Given a unit whose title differs from the catalog label, when Build Test is clicked, then the correct scope is still selected. | G37: Sprint 3 | H37: FE Dev | I37: 5 | J37: Medium | K37: To Do | L37: 46301 | M37: 46312
A38: ="TASK-"&TEXT(37,"000") | B38: UC-029 | C38: Practice test definition API | D38: Backend | E38: POST /assess/tests/practice with the allowlist derived from TEST_TYPE_CONFIG so it cannot drift from the engine. | F38: Given a valid exam and scope, when the endpoint is called, then a published test is created that any attempt flow can start. | G38: Sprint 1 | H38: BE Dev | I38: 3 | J38: Medium | K38: Done | L38: 46273 | M38: 46277
A39: ="TASK-"&TEXT(38,"000") | B39: UC-023 | C39: Live question availability while configuring | D39: Full-stack | E39: POST /assess/availability debounced from the configurator, surfaced by QuestionAvailabilityBanner. | F39: Given a config change, when the pool is short, then the banner warns before Start rather than after. | G39: Sprint 1 | H39: Full-stack | I39: 5 | J39: High | K39: Done | L39: 46273 | M39: 46277
A40: ="TASK-"&TEXT(39,"000") | B40: UC-024 | C40: Insufficient question pool dialog | D40: Frontend | E40: InsufficientQuestionsDialog covering the POOL-01..POOL-15 boundary cases in docs/TEST-CASES.md. | F40: Given a scope that is short, when the student starts, then no attempt row is created and the shortfall is spelled out. | G40: Sprint 1 | H40: FE Dev | I40: 3 | J40: Critical | K40: Done | L40: 46273 | M40: 46277
...

Sheet Sprint Board
B2: Sprint Summary
B4: Sprint | C4: Total Tasks | D4: To Do | E4: In Progress | F4: In Review | G4: Blocked | H4: Done | I4: Total Story Points
B5: Sprint 1 | C5: =COUNTIF('Sprint Tasks'!$G$3:$G$121,$B5) | D5: =COUNTIFS('Sprint Tasks'!$G$3:$G$121,$B5,'Sprint Tasks'!$K$3:$K$121,"To Do") | E5: =COUNTIFS('Sprint Tasks'!$G$3:$G$121,$B5,'Sprint Tasks'!$K$3:$K$121,"In Progress") | F5: =COUNTIFS('Sprint Tasks'!$G$3:$G$121,$B5,'Sprint Tasks'!$K$3:$K$121,"In Review") | G5: =COUNTIFS('Sprint Tasks'!$G$3:$G$121,$B5,'Sprint Tasks'!$K$3:$K$121,"Blocked") | H5: =COUNTIFS('Sprint Tasks'!$G$3:$G$121,$B5,'Sprint Tasks'!$K$3:$K$121,"Done") | I5: =SUMIF('Sprint Tasks'!$G$3:$G$121,$B5,'Sprint Tasks'!$I$3:$I$121)
B6: Sprint 2 | C6: =COUNTIF('Sprint Tasks'!$G$3:$G$121,$B6) | D6: =COUNTIFS('Sprint Tasks'!$G$3:$G$121,$B6,'Sprint Tasks'!$K$3:$K$121,"To Do") | E6: =COUNTIFS('Sprint Tasks'!$G$3:$G$121,$B6,'Sprint Tasks'!$K$3:$K$121,"In Progress") | F6: =COUNTIFS('Sprint Tasks'!$G$3:$G$121,$B6,'Sprint Tasks'!$K$3:$K$121,"In Review") | G6: =COUNTIFS('Sprint Tasks'!$G$3:$G$121,$B6,'Sprint Tasks'!$K$3:$K$121,"Blocked") | H6: =COUNTIFS('Sprint Tasks'!$G$3:$G$121,$B6,'Sprint Tasks'!$K$3:$K$121,"Done") | I6: =SUMIF('Sprint Tasks'!$G$3:$G$121,$B6,'Sprint Tasks'!$I$3:$I$121)
B7: Sprint 3 | C7: =COUNTIF('Sprint Tasks'!$G$3:$G$121,$B7) | D7: =COUNTIFS('Sprint Tasks'!$G$3:$G$121,$B7,'Sprint Tasks'!$K$3:$K$121,"To Do") | E7: =COUNTIFS('Sprint Tasks'!$G$3:$G$121,$B7,'Sprint Tasks'!$K$3:$K$121,"In Progress") | F7: =COUNTIFS('Sprint Tasks'!$G$3:$G$121,$B7,'Sprint Tasks'!$K$3:$K$121,"In Review") | G7: =COUNTIFS('Sprint Tasks'!$G$3:$G$121,$B7,'Sprint Tasks'!$K$3:$K$121,"Blocked") | H7: =COUNTIFS('Sprint Tasks'!$G$3:$G$121,$B7,'Sprint Tasks'!$K$3:$K$121,"Done") | I7: =SUMIF('Sprint Tasks'!$G$3:$G$121,$B7,'Sprint Tasks'!$I$3:$I$121)
B8: Sprint 4 | C8: =COUNTIF('Sprint Tasks'!$G$3:$G$121,$B8) | D8: =COUNTIFS('Sprint Tasks'!$G$3:$G$121,$B8,'Sprint Tasks'!$K$3:$K$121,"To Do") | E8: =COUNTIFS('Sprint Tasks'!$G$3:$G$121,$B8,'Sprint Tasks'!$K$3:$K$121,"In Progress") | F8: =COUNTIFS('Sprint Tasks'!$G$3:$G$121,$B8,'Sprint Tasks'!$K$3:$K$121,"In Review") | G8: =COUNTIFS('Sprint Tasks'!$G$3:$G$121,$B8,'Sprint Tasks'!$K$3:$K$121,"Blocked") | H8: =COUNTIFS('Sprint Tasks'!$G$3:$G$121,$B8,'Sprint Tasks'!$K$3:$K$121,"Done") | I8: =SUMIF('Sprint Tasks'!$G$3:$G$121,$B8,'Sprint Tasks'!$I$3:$I$121)
B9: Sprint 5 | C9: =COUNTIF('Sprint Tasks'!$G$3:$G$121,$B9) | D9: =COUNTIFS('Sprint Tasks'!$G$3:$G$121,$B9,'Sprint Tasks'!$K$3:$K$121,"To Do") | E9: =COUNTIFS('Sprint Tasks'!$G$3:$G$121,$B9,'Sprint Tasks'!$K$3:$K$121,"In Progress") | F9: =COUNTIFS('Sprint Tasks'!$G$3:$G$121,$B9,'Sprint Tasks'!$K$3:$K$121,"In Review") | G9: =COUNTIFS('Sprint Tasks'!$G$3:$G$121,$B9,'Sprint Tasks'!$K$3:$K$121,"Blocked") | H9: =COUNTIFS('Sprint Tasks'!$G$3:$G$121,$B9,'Sprint Tasks'!$K$3:$K$121,"Done") | I9: =SUMIF('Sprint Tasks'!$G$3:$G$121,$B9,'Sprint Tasks'!$I$3:$I$121)
B10: Backlog | C10: =COUNTIF('Sprint Tasks'!$G$3:$G$121,$B10) | D10: =COUNTIFS('Sprint Tasks'!$G$3:$G$121,$B10,'Sprint Tasks'!$K$3:$K$121,"To Do") | E10: =COUNTIFS('Sprint Tasks'!$G$3:$G$121,$B10,'Sprint Tasks'!$K$3:$K$121,"In Progress") | F10: =COUNTIFS('Sprint Tasks'!$G$3:$G$121,$B10,'Sprint Tasks'!$K$3:$K$121,"In Review") | G10: =COUNTIFS('Sprint Tasks'!$G$3:$G$121,$B10,'Sprint Tasks'!$K$3:$K$121,"Blocked") | H10: =COUNTIFS('Sprint Tasks'!$G$3:$G$121,$B10,'Sprint Tasks'!$K$3:$K$121,"Done") | I10: =SUMIF('Sprint Tasks'!$G$3:$G$121,$B10,'Sprint Tasks'!$I$3:$I$121)
B11: Total | C11: =SUM(C5:C10) | D11: =SUM(D5:D10) | E11: =SUM(E5:E10) | F11: =SUM(F5:F10) | G11: =SUM(G5:G10) | H11: =SUM(H5:H10) | I11: =SUM(I5:I10)
